Workbook

Sheet Employee Master
A1: Employee ID | B1: Employee Name | C1: Department | D1: Designation | E1: Employment Type | F1: Joining Date | G1: Monthly Salary | H1: Previous Experience Years | I1: Current Company Experience | J1: Total Experience | K1: PF Applicable | L1: PF Rate | M1: Employee PF | N1: Employer PF | O1: Employment Status
A2: EMP001 | B2: Rajesh Sharma | C2: IT | D2: Software Engineer | E2: Full-Time | F2: 44255 | G2: 48000 | H2: 0 | I2: =ROUND((DATE(2026,8,31)-F2)/365.25,1) -> 5.5 | J2: =ROUND(H2+I2,1) -> 5.5 | K2: Yes | L2: 0.12 | M2: =IF(K2="Yes",ROUND(G2*L2,0),0) -> 5760 | N2: =IF(K2="Yes",ROUND(G2*L2,0),0) -> 5760 | O2: Active
A3: EMP002 | B3: Geeta Shah | C3: Engineering | D3: Senior Software Engineer | E3: Full-Time | F3: 45171 | G3: 104500 | H3: 3.9 | I3: =ROUND((DATE(2026,8,31)-F3)/365.25,1) -> 3 | J3: =ROUND(H3+I3,1) -> 6.9 | K3: Yes | L3: 0.12 | M3: =IF(K3="Yes",ROUND(G3*L3,0),0) -> 12540 | N3: =IF(K3="Yes",ROUND(G3*L3,0),0) -> 12540 | O3: Active
A4: EMP003 | B4: Ajay Kumar | C4: HR | D4: HR Executive | E4: Full-Time | F4: 45699 | G4: 23000 | H4: 3.4 | I4: =ROUND((DATE(2026,8,31)-F4)/365.25,1) -> 1.5 | J4: =ROUND(H4+I4,1) -> 4.9 | K4: Yes | L4: 0.12 | M4: =IF(K4="Yes",ROUND(G4*L4,0),0) -> 2760 | N4: =IF(K4="Yes",ROUND(G4*L4,0),0) -> 2760 | O4: Active
A5: EMP004 | B5: Pooja Tiwari | C5: Finance | D5: Accountant | E5: Full-Time | F5: 43636 | G5: 33000 | H5: 5.1 | I5: =ROUND((DATE(2026,8,31)-F5)/365.25,1) -> 7.2 | J5: =ROUND(H5+I5,1) -> 12.3 | K5: Yes | L5: 0.12 | M5: =IF(K5="Yes",ROUND(G5*L5,0),0) -> 3960 | N5: =IF(K5="Yes",ROUND(G5*L5,0),0) -> 3960 | O5: Active
A6: EMP005 | B6: Vandana Gupta | C6: Accounts | D6: Senior Accountant | E6: Contract | F6: 45991 | G6: 81000 | H6: 3.4 | I6: =ROUND((DATE(2026,8,31)-F6)/365.25,1) -> 0.8 | J6: =ROUND(H6+I6,1) -> 4.2 | K6: Yes | L6: 0.12 | M6: =IF(K6="Yes",ROUND(G6*L6,0),0) -> 9720 | N6: =IF(K6="Yes",ROUND(G6*L6,0),0) -> 9720 | O6: Active
A7: EMP006 | B7: Seema Chauhan | C7: Sales | D7: Sales Executive | E7: Full-Time | F7: 45335 | G7: 23000 | H7: 0.3 | I7: =ROUND((DATE(2026,8,31)-F7)/365.25,1) -> 2.5 | J7: =ROUND(H7+I7,1) -> 2.8 | K7: Yes | L7: 0.12 | M7: =IF(K7="Yes",ROUND(G7*L7,0),0) -> 2760 | N7: =IF(K7="Yes",ROUND(G7*L7,0),0) -> 2760 | O7: Active
A8: EMP007 | B8: Vikram Sharma | C8: Marketing | D8: Marketing Executive | E8: Full-Time | F8: 43623 | G8: 34000 | H8: 0.3 | I8: =ROUND((DATE(2026,8,31)-F8)/365.25,1) -> 7.2 | J8: =ROUND(H8+I8,1) -> 7.5 | K8: Yes | L8: 0.12 | M8: =IF(K8="Yes",ROUND(G8*L8,0),0) -> 4080 | N8: =IF(K8="Yes",ROUND(G8*L8,0),0) -> 4080 | O8: Active
A9: EMP008 | B9: Deepika Mehta | C9: Operations | D9: Operations Executive | E9: Full-Time | F9: 43961 | G9: 30500 | H9: 0 | I9: =ROUND((DATE(2026,8,31)-F9)/365.25,1) -> 6.3 | J9: =ROUND(H9+I9,1) -> 6.3 | K9: Yes | L9: 0.12 | M9: =IF(K9="Yes",ROUND(G9*L9,0),0) -> 3660 | N9: =IF(K9="Yes",ROUND(G9*L9,0),0) -> 3660 | O9: Active
A10: EMP009 | B10: Nandini Agarwal | C10: Administration | D10: Office Administrator | E10: Full-Time | F10: 45643 | G10: 33500 | H10: 6 | I10: =ROUND((DATE(2026,8,31)-F10)/365.25,1) -> 1.7 | J10: =ROUND(H10+I10,1) -> 7.7 | K10: Yes | L10: 0.12 | M10: =IF(K10="Yes",ROUND(G10*L10,0),0) -> 4020 | N10: =IF(K10="Yes",ROUND(G10*L10,0),0) -> 4020 | O10: Active
A11: EMP010 | B11: Rachna Sharma | C11: Support | D11: Support Executive | E11: Contract | F11: 43826 | G11: 20500 | H11: 7.1 | I11: =ROUND((DATE(2026,8,31)-F11)/365.25,1) -> 6.7 | J11: =ROUND(H11+I11,1) -> 13.8 | K11: Yes | L11: 0.12 | M11: =IF(K11="Yes",ROUND(G11*L11,0),0) -> 2460 | N11: =IF(K11="Yes",ROUND(G11*L11,0),0) -> 2460 | O11: Active
A12: EMP011 | B12: Madhuri Mehta | C12: IT | D12: Senior Software Engineer | E12: Full-Time | F12: 45844 | G12: 124000 | H12: 6.9 | I12: =ROUND((DATE(2026,8,31)-F12)/365.25,1) -> 1.2 | J12: =ROUND(H12+I12,1) -> 8.1 | K12: Yes | L12: 0.12 | M12: =IF(K12="Yes",ROUND(G12*L12,0),0) -> 14880 | N12: =IF(K12="Yes",ROUND(G12*L12,0),0) -> 14880 | O12: Active
A13: EMP012 | B13: Vandana Chauhan | C13: Engineering | D13: Project Manager | E13: Full-Time | F13: 45973 | G13: 101000 | H13: 0.9 | I13: =ROUND((DATE(2026,8,31)-F13)/365.25,1) -> 0.8 | J13: =ROUND(H13+I13,1) -> 1.7 | K13: Yes | L13: 0.12 | M13: =IF(K13="Yes",ROUND(G13*L13,0),0) -> 12120 | N13: =IF(K13="Yes",ROUND(G13*L13,0),0) -> 12120 | O13: Active
... A201: EMP200 | B201: Pooja Chopra | C201: Support | D201: Business Analyst | E201: Full-Time | F201: 44219 | G201: 62000 | H201: 1.7 | I201: =ROUND((DATE(2026,8,31)-F201)/365.25,1) -> 5.6 | J201: =ROUND(H201+I201,1) -> 7.3 | K201: Yes | L201: 0.12 | M201: =IF(K201="Yes",ROUND(G201*L201,0),0) -> 7440 | N201: =IF(K201="Yes",ROUND(G201*L201,0),0) -> 7440 | O201: Active

Sheet Tally Attendance
A1: Employee ID | B1: Employee Name | C1: Department | D1: Date | E1: Day | F1: Attendance Status | G1: Check In | H1: Check Out | I1: Working Hours | J1: Leave Type | K1: Remarks
A2: EMP001 | B2: Rajesh Sharma | C2: IT | D2: 46235 | E2: =TEXT(D2,"dddd") -> Saturday | F2: Present | G2: 09:00 | H2: 18:00 | I2: =IF(F2="Present",9,IF(F2="Half Day",4,0)) -> 9
A3: EMP001 | B3: Rajesh Sharma | C3: IT | D3: 46236 | E3: =TEXT(D3,"dddd") -> Sunday | F3: Weekly Off | I3: =IF(F3="Present",9,IF(F3="Half Day",4,0)) -> 0 | K3: Weekly Off
A4: EMP001 | B4: Rajesh Sharma | C4: IT | D4: 46237 | E4: =TEXT(D4,"dddd") -> Monday | F4: Present | G4: 09:00 | H4: 18:00 | I4: =IF(F4="Present",9,IF(F4="Half Day",4,0)) -> 9
A5: EMP001 | B5: Rajesh Sharma | C5: IT | D5: 46238 | E5: =TEXT(D5,"dddd") -> Tuesday | F5: Present | G5: 09:00 | H5: 18:00 | I5: =IF(F5="Present",9,IF(F5="Half Day",4,0)) -> 9
A6: EMP001 | B6: Rajesh Sharma | C6: IT | D6: 46239 | E6: =TEXT(D6,"dddd") -> Wednesday | F6: Present | G6: 09:00 | H6: 18:00 | I6: =IF(F6="Present",9,IF(F6="Half Day",4,0)) -> 9
A7: EMP001 | B7: Rajesh Sharma | C7: IT | D7: 46240 | E7: =TEXT(D7,"dddd") -> Thursday | F7: Present | G7: 09:00 | H7: 18:00 | I7: =IF(F7="Present",9,IF(F7="Half Day",4,0)) -> 9
A8: EMP001 | B8: Rajesh Sharma | C8: IT | D8: 46241 | E8: =TEXT(D8,"dddd") -> Friday | F8: Present | G8: 09:00 | H8: 18:00 | I8: =IF(F8="Present",9,IF(F8="Half Day",4,0)) -> 9
A9: EMP001 | B9: Rajesh Sharma | C9: IT | D9: 46242 | E9: =TEXT(D9,"dddd") -> Saturday | F9: Present | G9: 09:00 | H9: 18:00 | I9: =IF(F9="Present",9,IF(F9="Half Day",4,0)) -> 9
A10: EMP001 | B10: Rajesh Sharma | C10: IT | D10: 46243 | E10: =TEXT(D10,"dddd") -> Sunday | F10: Weekly Off | I10: =IF(F10="Present",9,IF(F10="Half Day",4,0)) -> 0 | K10: Weekly Off
A11: EMP001 | B11: Rajesh Sharma | C11: IT | D11: 46244 | E11: =TEXT(D11,"dddd") -> Monday | F11: Present | G11: 09:00 | H11: 18:00 | I11: =IF(F11="Present",9,IF(F11="Half Day",4,0)) -> 9
A12: EMP001 | B12: Rajesh Sharma | C12: IT | D12: 46245 | E12: =TEXT(D12,"dddd") -> Tuesday | F12: Present | G12: 09:00 | H12: 18:00 | I12: =IF(F12="Present",9,IF(F12="Half Day",4,0)) -> 9
A13: EMP001 | B13: Rajesh Sharma | C13: IT | D13: 46246 | E13: =TEXT(D13,"dddd") -> Wednesday | F13: Present | G13: 09:00 | H13: 18:00 | I13: =IF(F13="Present",9,IF(F13="Half Day",4,0)) -> 9
A14: EMP001 | B14: Rajesh Sharma | C14: IT | D14: 46247 | E14: =TEXT(D14,"dddd") -> Thursday | F14: Present | G14: 09:00 | H14: 18:00 | I14: =IF(F14="Present",9,IF(F14="Half Day",4,0)) -> 9
A15: EMP001 | B15: Rajesh Sharma | C15: IT | D15: 46248 | E15: =TEXT(D15,"dddd") -> Friday | F15: Present | G15: 09:00 | H15: 18:00 | I15: =IF(F15="Present",9,IF(F15="Half Day",4,0)) -> 9
A16: EMP001 | B16: Rajesh Sharma | C16: IT | D16: 46249 | E16: =TEXT(D16,"dddd") -> Saturday | F16: Present | G16: 09:00 | H16: 18:00 | I16: =IF(F16="Present",9,IF(F16="Half Day",4,0)) -> 9
A17: EMP001 | B17: Rajesh Sharma | C17: IT | D17: 46250 | E17: =TEXT(D17,"dddd") -> Sunday | F17: Weekly Off | I17: =IF(F17="Present",9,IF(F17="Half Day",4,0)) -> 0 | K17: Weekly Off
A18: EMP001 | B18: Rajesh Sharma | C18: IT | D18: 46251 | E18: =TEXT(D18,"dddd") -> Monday | F18: Present | G18: 09:00 | H18: 18:00 | I18: =IF(F18="Present",9,IF(F18="Half Day",4,0)) -> 9
A19: EMP001 | B19: Rajesh Sharma | C19: IT | D19: 46252 | E19: =TEXT(D19,"dddd") -> Tuesday | F19: Present | G19: 09:00 | H19: 18:00 | I19: =IF(F19="Present",9,IF(F19="Half Day",4,0)) -> 9
A20: EMP001 | B20: Rajesh Sharma | C20: IT | D20: 46253 | E20: =TEXT(D20,"dddd") -> Wednesday | F20: Present | G20: 09:00 | H20: 18:00 | I20: =IF(F20="Present",9,IF(F20="Half Day",4,0)) -> 9
A21: EMP001 | B21: Rajesh Sharma | C21: IT | D21: 46254 | E21: =TEXT(D21,"dddd") -> Thursday | F21: Present | G21: 09:00 | H21: 18:00 | I21: =IF(F21="Present",9,IF(F21="Half Day",4,0)) -> 9
A22: EMP001 | B22: Rajesh Sharma | C22: IT | D22: 46255 | E22: =TEXT(D22,"dddd") -> Friday | F22: Present | G22: 09:00 | H22: 18:00 | I22: =IF(F22="Present",9,IF(F22="Half Day",4,0)) -> 9
A23: EMP001 | B23: Rajesh Sharma | C23: IT | D23: 46256 | E23: =TEXT(D23,"dddd") -> Saturday | F23: Present | G23: 09:00 | H23: 18:00 | I23: =IF(F23="Present",9,IF(F23="Half Day",4,0)) -> 9
A24: EMP001 | B24: Rajesh Sharma | C24: IT | D24: 46257 | E24: =TEXT(D24,"dddd") -> Sunday | F24: Weekly Off | I24: =IF(F24="Present",9,IF(F24="Half Day",4,0)) -> 0 | K24: Weekly Off
A25: EMP001 | B25: Rajesh Sharma | C25: IT | D25: 46258 | E25: =TEXT(D25,"dddd") -> Monday | F25: Present | G25: 09:00 | H25: 18:00 | I25: =IF(F25="Present",9,IF(F25="Half Day",4,0)) -> 9
A26: EMP001 | B26: Rajesh Sharma | C26: IT | D26: 46259 | E26: =TEXT(D26,"dddd") -> Tuesday | F26: Present | G26: 09:00 | H26: 18:00 | I26: =IF(F26="Present",9,IF(F26="Half Day",4,0)) -> 9
A27: EMP001 | B27: Rajesh Sharma | C27: IT | D27: 46260 | E27: =TEXT(D27,"dddd") -> Wednesday | F27: Present | G27: 09:00 | H27: 18:00 | I27: =IF(F27="Present",9,IF(F27="Half Day",4,0)) -> 9
A28: EMP001 | B28: Rajesh Sharma | C28: IT | D28: 46261 | E28: =TEXT(D28,"dddd") -> Thursday | F28: Present | G28: 09:00 | H28: 18:00 | I28: =IF(F28="Present",9,IF(F28="Half Day",4,0)) -> 9
A29: EMP001 | B29: Rajesh Sharma | C29: IT | D29: 46262 | E29: =TEXT(D29,"dddd") -> Friday | F29: Present | G29: 09:00 | H29: 18:00 | I29: =IF(F29="Present",9,IF(F29="Half Day",4,0)) -> 9
A30: EMP001 | B30: Rajesh Sharma | C30: IT | D30: 46263 | E30: =TEXT(D30,"dddd") -> Saturday | F30: Present | G30: 09:00 | H30: 18:00 | I30: =IF(F30="Present",9,IF(F30="Half Day",4,0)) -> 9
A31: EMP001 | B31: Rajesh Sharma | C31: IT | D31: 46264 | E31: =TEXT(D31,"dddd") -> Sunday | F31: Weekly Off | I31: =IF(F31="Present",9,IF(F31="Half Day",4,0)) -> 0 | K31: Weekly Off
A32: EMP001 | B32: Rajesh Sharma | C32: IT | D32: 46265 | E32: =TEXT(D32,"dddd") -> Monday | F32: Present | G32: 09:00 | H32: 18:00 | I32: =IF(F32="Present",9,IF(F32="Half Day",4,0)) -> 9
A33: EMP002 | B33: Geeta Shah | C33: Engineering | D33: 46235 | E33: =TEXT(D33,"dddd") -> Saturday | F33: Present | G33: 09:00 | H33: 18:00 | I33: =IF(F33="Present",9,IF(F33="Half Day",4,0)) -> 9
A34: EMP002 | B34: Geeta Shah | C34: Engineering | D34: 46236 | E34: =TEXT(D34,"dddd") -> Sunday | F34: Weekly Off | I34: =IF(F34="Present",9,IF(F34="Half Day",4,0)) -> 0 | K34: Weekly Off
A35: EMP002 | B35: Geeta Shah | C35: Engineering | D35: 46237 | E35: =TEXT(D35,"dddd") -> Monday | F35: Present | G35: 09:00 | H35: 18:00 | I35: =IF(F35="Present",9,IF(F35="Half Day",4,0)) -> 9
A36: EMP002 | B36: Geeta Shah | C36: Engineering | D36: 46238 | E36: =TEXT(D36,"dddd") -> Tuesday | F36: Present | G36: 09:00 | H36: 18:00 | I36: =IF(F36="Present",9,IF(F36="Half Day",4,0)) -> 9
A37: EMP002 | B37: Geeta Shah | C37: Engineering | D37: 46239 | E37: =TEXT(D37,"dddd") -> Wednesday | F37: Present | G37: 09:00 | H37: 18:00 | I37: =IF(F37="Present",9,IF(F37="Half Day",4,0)) -> 9
A38: EMP002 | B38: Geeta Shah | C38: Engineering | D38: 46240 | E38: =TEXT(D38,"dddd") -> Thursday | F38: Present | G38: 09:00 | H38: 18:00 | I38: =IF(F38="Present",9,IF(F38="Half Day",4,0)) -> 9
A39: EMP002 | B39: Geeta Shah | C39: Engineering | D39: 46241 | E39: =TEXT(D39,"dddd") -> Friday | F39: Present | G39: 09:00 | H39: 18:00 | I39: =IF(F39="Present",9,IF(F39="Half Day",4,0)) -> 9
A40: EMP002 | B40: Geeta Shah | C40: Engineering | D40: 46242 | E40: =TEXT(D40,"dddd") -> Saturday | F40: Present | G40: 09:00 | H40: 18:00 | I40: =IF(F40="Present",9,IF(F40="Half Day",4,0)) -> 9
...

Sheet Leave Records
A1: Leave ID | B1: Employee ID | C1: Employee Name | D1: Leave Date | E1: Leave Type | F1: Paid/Unpaid | G1: Leave Days | H1: Approval Status | I1: Reason
A2: LV0001 | B2: EMP003 | C2: Ajay Kumar | D2: 46251 | E2: Emergency Leave | F2: Paid | G2: 1 | H2: Pending | I2: Emergency Leave - personal reasons
A3: LV0002 | B3: EMP006 | C3: Seema Chauhan | D3: 46247 | E3: Unpaid Leave | F3: Unpaid | G3: 1 | H3: Pending | I3: Unpaid Leave - personal reasons
A4: LV0003 | B4: EMP009 | C4: Nandini Agarwal | D4: 46262 | E4: Paid Leave | F4: Paid | G4: 1 | H4: Approved | I4: Paid Leave - personal reasons
A5: LV0004 | B5: EMP010 | C5: Rachna Sharma | D5: 46259 | E5: Emergency Leave | F5: Paid | G5: 1 | H5: Approved | I5: Emergency Leave - personal reasons
A6: LV0005 | B6: EMP011 | C6: Madhuri Mehta | D6: 46244 | E6: Unpaid Leave | F6: Unpaid | G6: 1 | H6: Approved | I6: Unpaid Leave - personal reasons
A7: LV0006 | B7: EMP013 | C7: Ajay Malhotra | D7: 46240 | E7: Sick Leave | F7: Paid | G7: 1 | H7: Approved | I7: Sick Leave - personal reasons
A8: LV0007 | B8: EMP013 | C8: Ajay Malhotra | D8: 46252 | E8: Unpaid Leave | F8: Unpaid | G8: 1 | H8: Pending | I8: Unpaid Leave - personal reasons
A9: LV0008 | B9: EMP014 | C9: Seema Joshi | D9: 46256 | E9: Emergency Leave | F9: Paid | G9: 1 | H9: Approved | I9: Emergency Leave - personal reasons
A10: LV0009 | B10: EMP014 | C10: Seema Joshi | D10: 46262 | E10: Casual Leave | F10: Paid | G10: 1 | H10: Approved | I10: Casual Leave - personal reasons
A11: LV0010 | B11: EMP015 | C11: Aman Bhatia | D11: 46247 | E11: Unpaid Leave | F11: Unpaid | G11: 1 | H11: Approved | I11: Unpaid Leave - personal reasons
A12: LV0011 | B12: EMP015 | C12: Aman Bhatia | D12: 46259 | E12: Sick Leave | F12: Paid | G12: 1 | H12: Approved | I12: Sick Leave - personal reasons
A13: LV0012 | B13: EMP016 | C13: Amit Saxena | D13: 46240 | E13: Unpaid Leave | F13: Unpaid | G13: 1 | H13: Rejected | I13: Unpaid Leave - personal reasons
... A144: LV0143 | B144: EMP200 | C144: Pooja Chopra | D144: 46247 | E144: Unpaid Leave | F144: Unpaid | G144: 1 | H144: Approved | I144: Unpaid Leave - personal reasons

Sheet Salary Records
A1: Employee ID | B1: Employee Name | C1: Month | D1: Year | E1: Monthly Salary | F1: Working Days | G1: Present Days | H1: Absent Days | I1: Leave Days | J1: Half Days | K1: Free Leave Days | L1: Unpaid Absence Days | M1: Per Day Salary | N1: Gross Salary | O1: Absence Deduction | P1: Leave Deduction | Q1: Employee PF | R1: Other Deduction | S1: Net Salary
A2: EMP001 | B2: Rajesh Sharma | C2: August | D2: 2026 | E2: =INDEX('Employee Master'!$G$2:$G$201,MATCH(A2,'Employee Master'!$A$2:$A$201,0)) -> 48000 | F2: 26 | G2: =COUNTIFS('Tally Attendance'!$A$2:$A$6201,A2,'Tally Attendance'!$F$2:$F$6201,"Present") -> 26 | H2: =COUNTIFS('Tally Attendance'!$A$2:$A$6201,A2,'Tally Attendance'!$F$2:$F$6201,"Absent") -> 0 | I2: =COUNTIFS('Tally Attendance'!$A$2:$A$6201,A2,'Tally Attendance'!$F$2:$F$6201,"Leave") -> 0 | J2: =COUNTIFS('Tally Attendance'!$A$2:$A$6201,A2,'Tally Attendance'!$F$2:$F$6201,"Half Day") -> 0 | K2: =MIN(H2,2) -> 0 | L2: =MAX(H2-K2,0) -> 0 | M2: =ROUND(E2/F2,2) -> 1846.15 | N2: =E2 -> 48000 | O2: =ROUND(M2*L2,2) -> 0 | P2: =ROUND(M2*COUNTIFS('Leave Records'!$B$2:$B$144,A2,'Leave Records'!$F$2:$F$144,"Unpaid")+M2*0.5*J2,2) -> 0 | Q2: =INDEX('Employee Master'!$M$2:$M$201,MATCH(A2,'Employee Master'!$A$2:$A$201,0)) -> 5760 | R2: 0 | S2: =N2-O2-P2-Q2-R2 -> 42240
A3: EMP002 | B3: Geeta Shah | C3: August | D3: 2026 | E3: =INDEX('Employee Master'!$G$2:$G$201,MATCH(A3,'Employee Master'!$A$2:$A$201,0)) -> 104500 | F3: 26 | G3: =COUNTIFS('Tally Attendance'!$A$2:$A$6201,A3,'Tally Attendance'!$F$2:$F$6201,"Present") -> 26 | H3: =COUNTIFS('Tally Attendance'!$A$2:$A$6201,A3,'Tally Attendance'!$F$2:$F$6201,"Absent") -> 0 | I3: =COUNTIFS('Tally Attendance'!$A$2:$A$6201,A3,'Tally Attendance'!$F$2:$F$6201,"Leave") -> 0 | J3: =COUNTIFS('Tally Attendance'!$A$2:$A$6201,A3,'Tally Attendance'!$F$2:$F$6201,"Half Day") -> 0 | K3: =MIN(H3,2) -> 0 | L3: =MAX(H3-K3,0) -> 0 | M3: =ROUND(E3/F3,2) -> 4019.23 | N3: =E3 -> 104500 | O3: =ROUND(M3*L3,2) -> 0 | P3: =ROUND(M3*COUNTIFS('Leave Records'!$B$2:$B$144,A3,'Leave Records'!$F$2:$F$144,"Unpaid")+M3*0.5*J3,2) -> 0 | Q3: =INDEX('Employee Master'!$M$2:$M$201,MATCH(A3,'Employee Master'!$A$2:$A$201,0)) -> 12540 | R3: 0 | S3: =N3-O3-P3-Q3-R3 -> 91960
A4: EMP003 | B4: Ajay Kumar | C4: August | D4: 2026 | E4: =INDEX('Employee Master'!$G$2:$G$201,MATCH(A4,'Employee Master'!$A$2:$A$201,0)) -> 23000 | F4: 26 | G4: =COUNTIFS('Tally Attendance'!$A$2:$A$6201,A4,'Tally Attendance'!$F$2:$F$6201,"Present") -> 20 | H4: =COUNTIFS('Tally Attendance'!$A$2:$A$6201,A4,'Tally Attendance'!$F$2:$F$6201,"Absent") -> 5 | I4: =COUNTIFS('Tally Attendance'!$A$2:$A$6201,A4,'Tally Attendance'!$F$2:$F$6201,"Leave") -> 1 | J4: =COUNTIFS('Tally Attendance'!$A$2:$A$6201,A4,'Tally Attendance'!$F$2:$F$6201,"Half Day") -> 0 | K4: =MIN(H4,2) -> 2 | L4: =MAX(H4-K4,0) -> 3 | M4: =ROUND(E4/F4,2) -> 884.62 | N4: =E4 -> 23000 | O4: =ROUND(M4*L4,2) -> 2653.86 | P4: =ROUND(M4*COUNTIFS('Leave Records'!$B$2:$B$144,A4,'Leave Records'!$F$2:$F$144,"Unpaid")+M4*0.5*J4,2) -> 0 | Q4: =INDEX('Employee Master'!$M$2:$M$201,MATCH(A4,'Employee Master'!$A$2:$A$201,0)) -> 2760 | R4: 0 | S4: =N4-O4-P4-Q4-R4 -> 17586.14
A5: EMP004 | B5: Pooja Tiwari | C5: August | D5: 2026 | E5: =INDEX('Employee Master'!$G$2:$G$201,MATCH(A5,'Employee Master'!$A$2:$A$201,0)) -> 33000 | F5: 26 | G5: =COUNTIFS('Tally Attendance'!$A$2:$A$6201,A5,'Tally Attendance'!$F$2:$F$6201,"Present") -> 24 | H5: =COUNTIFS('Tally Attendance'!$A$2:$A$6201,A5,'Tally Attendance'!$F$2:$F$6201,"Absent") -> 2 | I5: =COUNTIFS('Tally Attendance'!$A$2:$A$6201,A5,'Tally Attendance'!$F$2:$F$6201,"Leave") -> 0 | J5: =COUNTIFS('Tally Attendance'!$A$2:$A$6201,A5,'Tally Attendance'!$F$2:$F$6201,"Half Day") -> 0 | K5: =MIN(H5,2) -> 2 | L5: =MAX(H5-K5,0) -> 0 | M5: =ROUND(E5/F5,2) -> 1269.23 | N5: =E5 -> 33000 | O5: =ROUND(M5*L5,2) -> 0 | P5: =ROUND(M5*COUNTIFS('Leave Records'!$B$2:$B$144,A5,'Leave Records'!$F$2:$F$144,"Unpaid")+M5*0.5*J5,2) -> 0 | Q5: =INDEX('Employee Master'!$M$2:$M$201,MATCH(A5,'Employee Master'!$A$2:$A$201,0)) -> 3960 | R5: 0 | S5: =N5-O5-P5-Q5-R5 -> 29040
A6: EMP005 | B6: Vandana Gupta | C6: August | D6: 2026 | E6: =INDEX('Employee Master'!$G$2:$G$201,MATCH(A6,'Employee Master'!$A$2:$A$201,0)) -> 81000 | F6: 26 | G6: =COUNTIFS('Tally Attendance'!$A$2:$A$6201,A6,'Tally Attendance'!$F$2:$F$6201,"Present") -> 25 | H6: =COUNTIFS('Tally Attendance'!$A$2:$A$6201,A6,'Tally Attendance'!$F$2:$F$6201,"Absent") -> 1 | I6: =COUNTIFS('Tally Attendance'!$A$2:$A$6201,A6,'Tally Attendance'!$F$2:$F$6201,"Leave") -> 0 | J6: =COUNTIFS('Tally Attendance'!$A$2:$A$6201,A6,'Tally Attendance'!$F$2:$F$6201,"Half Day") -> 0 | K6: =MIN(H6,2) -> 1 | L6: =MAX(H6-K6,0) -> 0 | M6: =ROUND(E6/F6,2) -> 3115.38 | N6: =E6 -> 81000 | O6: =ROUND(M6*L6,2) -> 0 | P6: =ROUND(M6*COUNTIFS('Leave Records'!$B$2:$B$144,A6,'Leave Records'!$F$2:$F$144,"Unpaid")+M6*0.5*J6,2) -> 0 | Q6: =INDEX('Employee Master'!$M$2:$M$201,MATCH(A6,'Employee Master'!$A$2:$A$201,0)) -> 9720 | R6: 0 | S6: =N6-O6-P6-Q6-R6 -> 71280
A7: EMP006 | B7: Seema Chauhan | C7: August | D7: 2026 | E7: =INDEX('Employee Master'!$G$2:$G$201,MATCH(A7,'Employee Master'!$A$2:$A$201,0)) -> 23000 | F7: 26 | G7: =COUNTIFS('Tally Attendance'!$A$2:$A$6201,A7,'Tally Attendance'!$F$2:$F$6201,"Present") -> 20 | H7: =COUNTIFS('Tally Attendance'!$A$2:$A$6201,A7,'Tally Attendance'!$F$2:$F$6201,"Absent") -> 3 | I7: =COUNTIFS('Tally Attendance'!$A$2:$A$6201,A7,'Tally Attendance'!$F$2:$F$6201,"Leave") -> 1 | J7: =COUNTIFS('Tally Attendance'!$A$2:$A$6201,A7,'Tally Attendance'!$F$2:$F$6201,"Half Day") -> 2 | K7: =MIN(H7,2) -> 2 | L7: =MAX(H7-K7,0) -> 1 | M7: =ROUND(E7/F7,2) -> 884.62 | N7: =E7 -> 23000 | O7: =ROUND(M7*L7,2) -> 884.62 | P7: =ROUND(M7*COUNTIFS('Leave Records'!$B$2:$B$144,A7,'Leave Records'!$F$2:$F$144,"Unpaid")+M7*0.5*J7,2) -> 1769.24 | Q7: =INDEX('Employee Master'!$M$2:$M$201,MATCH(A7,'Employee Master'!$A$2:$A$201,0)) -> 2760 | R7: 0 | S7: =N7-O7-P7-Q7-R7 -> 17586.14
A8: EMP007 | B8: Vikram Sharma | C8: August | D8: 2026 | E8: =INDEX('Employee Master'!$G$2:$G$201,MATCH(A8,'Employee Master'!$A$2:$A$201,0)) -> 34000 | F8: 26 | G8: =COUNTIFS('Tally Attendance'!$A$2:$A$6201,A8,'Tally Attendance'!$F$2:$F$6201,"Present") -> 26 | H8: =COUNTIFS('Tally Attendance'!$A$2:$A$6201,A8,'Tally Attendance'!$F$2:$F$6201,"Absent") -> 0 | I8: =COUNTIFS('Tally Attendance'!$A$2:$A$6201,A8,'Tally Attendance'!$F$2:$F$6201,"Leave") -> 0 | J8: =COUNTIFS('Tally Attendance'!$A$2:$A$6201,A8,'Tally Attendance'!$F$2:$F$6201,"Half Day") -> 0 | K8: =MIN(H8,2) -> 0 | L8: =MAX(H8-K8,0) -> 0 | M8: =ROUND(E8/F8,2) -> 1307.69 | N8: =E8 -> 34000 | O8: =ROUND(M8*L8,2) -> 0 | P8: =ROUND(M8*COUNTIFS('Leave Records'!$B$2:$B$144,A8,'Leave Records'!$F$2:$F$144,"Unpaid")+M8*0.5*J8,2) -> 0 | Q8: =INDEX('Employee Master'!$M$2:$M$201,MATCH(A8,'Employee Master'!$A$2:$A$201,0)) -> 4080 | R8: 0 | S8: =N8-O8-P8-Q8-R8 -> 29920
A9: EMP008 | B9: Deepika Mehta | C9: August | D9: 2026 | E9: =INDEX('Employee Master'!$G$2:$G$201,MATCH(A9,'Employee Master'!$A$2:$A$201,0)) -> 30500 | F9: 26 | G9: =COUNTIFS('Tally Attendance'!$A$2:$A$6201,A9,'Tally Attendance'!$F$2:$F$6201,"Present") -> 26 | H9: =COUNTIFS('Tally Attendance'!$A$2:$A$6201,A9,'Tally Attendance'!$F$2:$F$6201,"Absent") -> 0 | I9: =COUNTIFS('Tally Attendance'!$A$2:$A$6201,A9,'Tally Attendance'!$F$2:$F$6201,"Leave") -> 0 | J9: =COUNTIFS('Tally Attendance'!$A$2:$A$6201,A9,'Tally Attendance'!$F$2:$F$6201,"Half Day") -> 0 | K9: =MIN(H9,2) -> 0 | L9: =MAX(H9-K9,0) -> 0 | M9: =ROUND(E9/F9,2) -> 1173.08 | N9: =E9 -> 30500 | O9: =ROUND(M9*L9,2) -> 0 | P9: =ROUND(M9*COUNTIFS('Leave Records'!$B$2:$B$144,A9,'Leave Records'!$F$2:$F$144,"Unpaid")+M9*0.5*J9,2) -> 0 | Q9: =INDEX('Employee Master'!$M$2:$M$201,MATCH(A9,'Employee Master'!$A$2:$A$201,0)) -> 3660 | R9: 0 | S9: =N9-O9-P9-Q9-R9 -> 26840
A10: EMP009 | B10: Nandini Agarwal | C10: August | D10: 2026 | E10: =INDEX('Employee Master'!$G$2:$G$201,MATCH(A10,'Employee Master'!$A$2:$A$201,0)) -> 33500 | F10: 26 | G10: =COUNTIFS('Tally Attendance'!$A$2:$A$6201,A10,'Tally Attendance'!$F$2:$F$6201,"Present") -> 16 | H10: =COUNTIFS('Tally Attendance'!$A$2:$A$6201,A10,'Tally Attendance'!$F$2:$F$6201,"Absent") -> 9 | I10: =COUNTIFS('Tally Attendance'!$A$2:$A$6201,A10,'Tally Attendance'!$F$2:$F$6201,"Leave") -> 1 | J10: =COUNTIFS('Tally Attendance'!$A$2:$A$6201,A10,'Tally Attendance'!$F$2:$F$6201,"Half Day") -> 0 | K10: =MIN(H10,2) -> 2 | L10: =MAX(H10-K10,0) -> 7 | M10: =ROUND(E10/F10,2) -> 1288.46 | N10: =E10 -> 33500 | O10: =ROUND(M10*L10,2) -> 9019.22 | P10: =ROUND(M10*COUNTIFS('Leave Records'!$B$2:$B$144,A10,'Leave Records'!$F$2:$F$144,"Unpaid")+M10*0.5*J10,2) -> 0 | Q10: =INDEX('Employee Master'!$M$2:$M$201,MATCH(A10,'Employee Master'!$A$2:$A$201,0)) -> 4020 | R10: 0 | S10: =N10-O10-P10-Q10-R10 -> 20460.78
A11: EMP010 | B11: Rachna Sharma | C11: August | D11: 2026 | E11: =INDEX('Employee Master'!$G$2:$G$201,MATCH(A11,'Employee Master'!$A$2:$A$201,0)) -> 20500 | F11: 26 | G11: =COUNTIFS('Tally Attendance'!$A$2:$A$6201,A11,'Tally Attendance'!$F$2:$F$6201,"Present") -> 18 | H11: =COUNTIFS('Tally Attendance'!$A$2:$A$6201,A11,'Tally Attendance'!$F$2:$F$6201,"Absent") -> 5 | I11: =COUNTIFS('Tally Attendance'!$A$2:$A$6201,A11,'Tally Attendance'!$F$2:$F$6201,"Leave") -> 1 | J11: =COUNTIFS('Tally Attendance'!$A$2:$A$6201,A11,'Tally Attendance'!$F$2:$F$6201,"Half Day") -> 2 | K11: =MIN(H11,2) -> 2 | L11: =MAX(H11-K11,0) -> 3 | M11: =ROUND(E11/F11,2) -> 788.46 | N11: =E11 -> 20500 | O11: =ROUND(M11*L11,2) -> 2365.38 | P11: =ROUND(M11*COUNTIFS('Leave Records'!$B$2:$B$144,A11,'Leave Records'!$F$2:$F$144,"Unpaid")+M11*0.5*J11,2) -> 788.46 | Q11: =INDEX('Employee Master'!$M$2:$M$201,MATCH(A11,'Employee Master'!$A$2:$A$201,0)) -> 2460 | R11: 0 | S11: =N11-O11-P11-Q11-R11 -> 14886.16
A12: EMP011 | B12: Madhuri Mehta | C12: August | D12: 2026 | E12: =INDEX('Employee Master'!$G$2:$G$201,MATCH(A12,'Employee Master'!$A$2:$A$201,0)) -> 124000 | F12: 26 | G12: =COUNTIFS('Tally Attendance'!$A$2:$A$6201,A12,'Tally Attendance'!$F$2:$F$6201,"Present") -> 23 | H12: =COUNTIFS('Tally Attendance'!$A$2:$A$6201,A12,'Tally Attendance'!$F$2:$F$6201,"Absent") -> 2 | I12: =COUNTIFS('Tally Attendance'!$A$2:$A$6201,A12,'Tally Attendance'!$F$2:$F$6201,"Leave") -> 1 | J12: =COUNTIFS('Tally Attendance'!$A$2:$A$6201,A12,'Tally Attendance'!$F$2:$F$6201,"Half Day") -> 0 | K12: =MIN(H12,2) -> 2 | L12: =MAX(H12-K12,0) -> 0 | M12: =ROUND(E12/F12,2) -> 4769.23 | N12: =E12 -> 124000 | O12: =ROUND(M12*L12,2) -> 0 | P12: =ROUND(M12*COUNTIFS('Leave Records'!$B$2:$B$144,A12,'Leave Records'!$F$2:$F$144,"Unpaid")+M12*0.5*J12,2) -> 4769.23 | Q12: =INDEX('Employee Master'!$M$2:$M$201,MATCH(A12,'Employee Master'!$A$2:$A$201,0)) -> 14880 | R12: 0 | S12: =N12-O12-P12-Q12-R12 -> 104350.77
A13: EMP012 | B13: Vandana Chauhan | C13: August | D13: 2026 | E13: =INDEX('Employee Master'!$G$2:$G$201,MATCH(A13,'Employee Master'!$A$2:$A$201,0)) -> 101000 | F13: 26 | G13: =COUNTIFS('Tally Attendance'!$A$2:$A$6201,A13,'Tally Attendance'!$F$2:$F$6201,"Present") -> 26 | H13: =COUNTIFS('Tally Attendance'!$A$2:$A$6201,A13,'Tally Attendance'!$F$2:$F$6201,"Absent") -> 0 | I13: =COUNTIFS('Tally Attendance'!$A$2:$A$6201,A13,'Tally Attendance'!$F$2:$F$6201,"Leave") -> 0 | J13: =COUNTIFS('Tally Attendance'!$A$2:$A$6201,A13,'Tally Attendance'!$F$2:$F$6201,"Half Day") -> 0 | K13: =MIN(H13,2) -> 0 | L13: =MAX(H13-K13,0) -> 0 | M13: =ROUND(E13/F13,2) -> 3884.62 | N13: =E13 -> 101000 | O13: =ROUND(M13*L13,2) -> 0 | P13: =ROUND(M13*COUNTIFS('Leave Records'!$B$2:$B$144,A13,'Leave Records'!$F$2:$F$144,"Unpaid")+M13*0.5*J13,2) -> 0 | Q13: =INDEX('Employee Master'!$M$2:$M$201,MATCH(A13,'Employee Master'!$A$2:$A$201,0)) -> 12120 | R13: 0 | S13: =N13-O13-P13-Q13-R13 -> 88880
... A201: EMP200 | B201: Pooja Chopra | C201: August | D201: 2026 | E201: =INDEX('Employee Master'!$G$2:$G$201,MATCH(A201,'Employee Master'!$A$2:$A$201,0)) -> 62000 | F201: 26 | G201: =COUNTIFS('Tally Attendance'!$A$2:$A$6201,A201,'Tally Attendance'!$F$2:$F$6201,"Present") -> 21 | H201: =COUNTIFS('Tally Attendance'!$A$2:$A$6201,A201,'Tally Attendance'!$F$2:$F$6201,"Absent") -> 2 | I201: =COUNTIFS('Tally Attendance'!$A$2:$A$6201,A201,'Tally Attendance'!$F$2:$F$6201,"Leave") -> 1 | J201: =COUNTIFS('Tally Attendance'!$A$2:$A$6201,A201,'Tally Attendance'!$F$2:$F$6201,"Half Day") -> 2 | K201: =MIN(H201,2) -> 2 | L201: =MAX(H201-K201,0) -> 0 | M201: =ROUND(E201/F201,2) -> 2384.62 | N201: =E201 -> 62000 | O201: =ROUND(M201*L201,2) -> 0 | P201: =ROUND(M201*COUNTIFS('Leave Records'!$B$2:$B$144,A201,'Leave Records'!$F$2:$F$144,"Unpaid")+M201*0.5*J201,2) -> 4769.24 | Q201: =INDEX('Employee Master'!$M$2:$M$201,MATCH(A201,'Employee Master'!$A$2:$A$201,0)) -> 7440 | R201: 0 | S201: =N201-O201-P201-Q201-R201 -> 49790.76

Sheet PF Records
A1: Employee ID | B1: Employee Name | C1: Month | D1: Year | E1: PF Applicable | F1: PF Rate | G1: PF Wage | H1: Employee PF | I1: Employer PF | J1: Total PF | K1: PF Status
A2: EMP001 | B2: Rajesh Sharma | C2: August | D2: 2026 | E2: =INDEX('Employee Master'!$K$2:$K$201,MATCH(A2,'Employee Master'!$A$2:$A$201,0)) -> Yes | F2: =INDEX('Employee Master'!$L$2:$L$201,MATCH(A2,'Employee Master'!$A$2:$A$201,0)) -> 0.12 | G2: =INDEX('Employee Master'!$G$2:$G$201,MATCH(A2,'Employee Master'!$A$2:$A$201,0)) -> 48000 | H2: =IF(E2="Yes",ROUND(G2*F2,0),0) -> 5760 | I2: =IF(E2="Yes",ROUND(G2*F2,0),0) -> 5760 | J2: =H2+I2 -> 11520 | K2: =IF(E2="Yes","Generated","Not Applicable") -> Generated
A3: EMP002 | B3: Geeta Shah | C3: August | D3: 2026 | E3: =INDEX('Employee Master'!$K$2:$K$201,MATCH(A3,'Employee Master'!$A$2:$A$201,0)) -> Yes | F3: =INDEX('Employee Master'!$L$2:$L$201,MATCH(A3,'Employee Master'!$A$2:$A$201,0)) -> 0.12 | G3: =INDEX('Employee Master'!$G$2:$G$201,MATCH(A3,'Employee Master'!$A$2:$A$201,0)) -> 104500 | H3: =IF(E3="Yes",ROUND(G3*F3,0),0) -> 12540 | I3: =IF(E3="Yes",ROUND(G3*F3,0),0) -> 12540 | J3: =H3+I3 -> 25080 | K3: =IF(E3="Yes","Generated","Not Applicable") -> Generated
A4: EMP003 | B4: Ajay Kumar | C4: August | D4: 2026 | E4: =INDEX('Employee Master'!$K$2:$K$201,MATCH(A4,'Employee Master'!$A$2:$A$201,0)) -> Yes | F4: =INDEX('Employee Master'!$L$2:$L$201,MATCH(A4,'Employee Master'!$A$2:$A$201,0)) -> 0.12 | G4: =INDEX('Employee Master'!$G$2:$G$201,MATCH(A4,'Employee Master'!$A$2:$A$201,0)) -> 23000 | H4: =IF(E4="Yes",ROUND(G4*F4,0),0) -> 2760 | I4: =IF(E4="Yes",ROUND(G4*F4,0),0) -> 2760 | J4: =H4+I4 -> 5520 | K4: =IF(E4="Yes","Generated","Not Applicable") -> Generated
A5: EMP004 | B5: Pooja Tiwari | C5: August | D5: 2026 | E5: =INDEX('Employee Master'!$K$2:$K$201,MATCH(A5,'Employee Master'!$A$2:$A$201,0)) -> Yes | F5: =INDEX('Employee Master'!$L$2:$L$201,MATCH(A5,'Employee Master'!$A$2:$A$201,0)) -> 0.12 | G5: =INDEX('Employee Master'!$G$2:$G$201,MATCH(A5,'Employee Master'!$A$2:$A$201,0)) -> 33000 | H5: =IF(E5="Yes",ROUND(G5*F5,0),0) -> 3960 | I5: =IF(E5="Yes",ROUND(G5*F5,0),0) -> 3960 | J5: =H5+I5 -> 7920 | K5: =IF(E5="Yes","Generated","Not Applicable") -> Generated
A6: EMP005 | B6: Vandana Gupta | C6: August | D6: 2026 | E6: =INDEX('Employee Master'!$K$2:$K$201,MATCH(A6,'Employee Master'!$A$2:$A$201,0)) -> Yes | F6: =INDEX('Employee Master'!$L$2:$L$201,MATCH(A6,'Employee Master'!$A$2:$A$201,0)) -> 0.12 | G6: =INDEX('Employee Master'!$G$2:$G$201,MATCH(A6,'Employee Master'!$A$2:$A$201,0)) -> 81000 | H6: =IF(E6="Yes",ROUND(G6*F6,0),0) -> 9720 | I6: =IF(E6="Yes",ROUND(G6*F6,0),0) -> 9720 | J6: =H6+I6 -> 19440 | K6: =IF(E6="Yes","Generated","Not Applicable") -> Generated
A7: EMP006 | B7: Seema Chauhan | C7: August | D7: 2026 | E7: =INDEX('Employee Master'!$K$2:$K$201,MATCH(A7,'Employee Master'!$A$2:$A$201,0)) -> Yes | F7: =INDEX('Employee Master'!$L$2:$L$201,MATCH(A7,'Employee Master'!$A$2:$A$201,0)) -> 0.12 | G7: =INDEX('Employee Master'!$G$2:$G$201,MATCH(A7,'Employee Master'!$A$2:$A$201,0)) -> 23000 | H7: =IF(E7="Yes",ROUND(G7*F7,0),0) -> 2760 | I7: =IF(E7="Yes",ROUND(G7*F7,0),0) -> 2760 | J7: =H7+I7 -> 5520 | K7: =IF(E7="Yes","Generated","Not Applicable") -> Generated
A8: EMP007 | B8: Vikram Sharma | C8: August | D8: 2026 | E8: =INDEX('Employee Master'!$K$2:$K$201,MATCH(A8,'Employee Master'!$A$2:$A$201,0)) -> Yes | F8: =INDEX('Employee Master'!$L$2:$L$201,MATCH(A8,'Employee Master'!$A$2:$A$201,0)) -> 0.12 | G8: =INDEX('Employee Master'!$G$2:$G$201,MATCH(A8,'Employee Master'!$A$2:$A$201,0)) -> 34000 | H8: =IF(E8="Yes",ROUND(G8*F8,0),0) -> 4080 | I8: =IF(E8="Yes",ROUND(G8*F8,0),0) -> 4080 | J8: =H8+I8 -> 8160 | K8: =IF(E8="Yes","Generated","Not Applicable") -> Generated
A9: EMP008 | B9: Deepika Mehta | C9: August | D9: 2026 | E9: =INDEX('Employee Master'!$K$2:$K$201,MATCH(A9,'Employee Master'!$A$2:$A$201,0)) -> Yes | F9: =INDEX('Employee Master'!$L$2:$L$201,MATCH(A9,'Employee Master'!$A$2:$A$201,0)) -> 0.12 | G9: =INDEX('Employee Master'!$G$2:$G$201,MATCH(A9,'Employee Master'!$A$2:$A$201,0)) -> 30500 | H9: =IF(E9="Yes",ROUND(G9*F9,0),0) -> 3660 | I9: =IF(E9="Yes",ROUND(G9*F9,0),0) -> 3660 | J9: =H9+I9 -> 7320 | K9: =IF(E9="Yes","Generated","Not Applicable") -> Generated
A10: EMP009 | B10: Nandini Agarwal | C10: August | D10: 2026 | E10: =INDEX('Employee Master'!$K$2:$K$201,MATCH(A10,'Employee Master'!$A$2:$A$201,0)) -> Yes | F10: =INDEX('Employee Master'!$L$2:$L$201,MATCH(A10,'Employee Master'!$A$2:$A$201,0)) -> 0.12 | G10: =INDEX('Employee Master'!$G$2:$G$201,MATCH(A10,'Employee Master'!$A$2:$A$201,0)) -> 33500 | H10: =IF(E10="Yes",ROUND(G10*F10,0),0) -> 4020 | I10: =IF(E10="Yes",ROUND(G10*F10,0),0) -> 4020 | J10: =H10+I10 -> 8040 | K10: =IF(E10="Yes","Generated","Not Applicable") -> Generated
A11: EMP010 | B11: Rachna Sharma | C11: August | D11: 2026 | E11: =INDEX('Employee Master'!$K$2:$K$201,MATCH(A11,'Employee Master'!$A$2:$A$201,0)) -> Yes | F11: =INDEX('Employee Master'!$L$2:$L$201,MATCH(A11,'Employee Master'!$A$2:$A$201,0)) -> 0.12 | G11: =INDEX('Employee Master'!$G$2:$G$201,MATCH(A11,'Employee Master'!$A$2:$A$201,0)) -> 20500 | H11: =IF(E11="Yes",ROUND(G11*F11,0),0) -> 2460 | I11: =IF(E11="Yes",ROUND(G11*F11,0),0) -> 2460 | J11: =H11+I11 -> 4920 | K11: =IF(E11="Yes","Generated","Not Applicable") -> Generated
A12: EMP011 | B12: Madhuri Mehta | C12: August | D12: 2026 | E12: =INDEX('Employee Master'!$K$2:$K$201,MATCH(A12,'Employee Master'!$A$2:$A$201,0)) -> Yes | F12: =INDEX('Employee Master'!$L$2:$L$201,MATCH(A12,'Employee Master'!$A$2:$A$201,0)) -> 0.12 | G12: =INDEX('Employee Master'!$G$2:$G$201,MATCH(A12,'Employee Master'!$A$2:$A$201,0)) -> 124000 | H12: =IF(E12="Yes",ROUND(G12*F12,0),0) -> 14880 | I12: =IF(E12="Yes",ROUND(G12*F12,0),0) -> 14880 | J12: =H12+I12 -> 29760 | K12: =IF(E12="Yes","Generated","Not Applicable") -> Generated
A13: EMP012 | B13: Vandana Chauhan | C13: August | D13: 2026 | E13: =INDEX('Employee Master'!$K$2:$K$201,MATCH(A13,'Employee Master'!$A$2:$A$201,0)) -> Yes | F13: =INDEX('Employee Master'!$L$2:$L$201,MATCH(A13,'Employee Master'!$A$2:$A$201,0)) -> 0.12 | G13: =INDEX('Employee Master'!$G$2:$G$201,MATCH(A13,'Employee Master'!$A$2:$A$201,0)) -> 101000 | H13: =IF(E13="Yes",ROUND(G13*F13,0),0) -> 12120 | I13: =IF(E13="Yes",ROUND(G13*F13,0),0) -> 12120 | J13: =H13+I13 -> 24240 | K13: =IF(E13="Yes","Generated","Not Applicable") -> Generated
... A201: EMP200 | B201: Pooja Chopra | C201: August | D201: 2026 | E201: =INDEX('Employee Master'!$K$2:$K$201,MATCH(A201,'Employee Master'!$A$2:$A$201,0)) -> Yes | F201: =INDEX('Employee Master'!$L$2:$L$201,MATCH(A201,'Employee Master'!$A$2:$A$201,0)) -> 0.12 | G201: =INDEX('Employee Master'!$G$2:$G$201,MATCH(A201,'Employee Master'!$A$2:$A$201,0)) -> 62000 | H201: =IF(E201="Yes",ROUND(G201*F201,0),0) -> 7440 | I201: =IF(E201="Yes",ROUND(G201*F201,0),0) -> 7440 | J201: =H201+I201 -> 14880 | K201: =IF(E201="Yes","Generated","Not Applicable") -> Generated

Sheet Monthly Summary
A1: Employee ID | B1: Employee Name | C1: Department | D1: Month | E1: Working Days | F1: Present Days | G1: Absent Days | H1: Leave Days | I1: Half Days | J1: Attendance Percentage | K1: Free Leave Allowed | L1: Free Leave Used | M1: Unpaid Absence Days | N1: Monthly Salary | O1: Absence Deduction | P1: Employee PF | Q1: Employer PF | R1: Total PF | S1: Net Salary | T1: Current Company Experience | U1: Previous Experience | V1: Total Experience
A2: EMP001 | B2: Rajesh Sharma | C2: IT | D2: August 2026 | E2: =INDEX('Salary Records'!$F$2:$F$201,MATCH(A2,'Salary Records'!$A$2:$A$201,0)) -> 26 | F2: =INDEX('Salary Records'!$G$2:$G$201,MATCH(A2,'Salary Records'!$A$2:$A$201,0)) -> 26 | G2: =INDEX('Salary Records'!$H$2:$H$201,MATCH(A2,'Salary Records'!$A$2:$A$201,0)) -> 0 | H2: =INDEX('Salary Records'!$I$2:$I$201,MATCH(A2,'Salary Records'!$A$2:$A$201,0)) -> 0 | I2: =INDEX('Salary Records'!$J$2:$J$201,MATCH(A2,'Salary Records'!$A$2:$A$201,0)) -> 0 | J2: =ROUND(F2/E2*100,1) -> 100 | K2: 2 | L2: =INDEX('Salary Records'!$K$2:$K$201,MATCH(A2,'Salary Records'!$A$2:$A$201,0)) -> 0 | M2: =INDEX('Salary Records'!$L$2:$L$201,MATCH(A2,'Salary Records'!$A$2:$A$201,0)) -> 0 | N2: =INDEX('Salary Records'!$E$2:$E$201,MATCH(A2,'Salary Records'!$A$2:$A$201,0)) -> 48000 | O2: =INDEX('Salary Records'!$O$2:$O$201,MATCH(A2,'Salary Records'!$A$2:$A$201,0)) -> 0 | P2: =INDEX('PF Records'!$H$2:$H$201,MATCH(A2,'PF Records'!$A$2:$A$201,0)) -> 5760 | Q2: =INDEX('PF Records'!$I$2:$I$201,MATCH(A2,'PF Records'!$A$2:$A$201,0)) -> 5760 | R2: =P2+Q2 -> 11520 | S2: =INDEX('Salary Records'!$S$2:$S$201,MATCH(A2,'Salary Records'!$A$2:$A$201,0)) -> 42240 | T2: =INDEX('Employee Master'!$I$2:$I$201,MATCH(A2,'Employee Master'!$A$2:$A$201,0)) -> 5.5 | U2: =INDEX('Employee Master'!$H$2:$H$201,MATCH(A2,'Employee Master'!$A$2:$A$201,0)) -> 0 | V2: =INDEX('Employee Master'!$J$2:$J$201,MATCH(A2,'Employee Master'!$A$2:$A$201,0)) -> 5.5
A3: EMP002 | B3: Geeta Shah | C3: Engineering | D3: August 2026 | E3: =INDEX('Salary Records'!$F$2:$F$201,MATCH(A3,'Salary Records'!$A$2:$A$201,0)) -> 26 | F3: =INDEX('Salary Records'!$G$2:$G$201,MATCH(A3,'Salary Records'!$A$2:$A$201,0)) -> 26 | G3: =INDEX('Salary Records'!$H$2:$H$201,MATCH(A3,'Salary Records'!$A$2:$A$201,0)) -> 0 | H3: =INDEX('Salary Records'!$I$2:$I$201,MATCH(A3,'Salary Records'!$A$2:$A$201,0)) -> 0 | I3: =INDEX('Salary Records'!$J$2:$J$201,MATCH(A3,'Salary Records'!$A$2:$A$201,0)) -> 0 | J3: =ROUND(F3/E3*100,1) -> 100 | K3: 2 | L3: =INDEX('Salary Records'!$K$2:$K$201,MATCH(A3,'Salary Records'!$A$2:$A$201,0)) -> 0 | M3: =INDEX('Salary Records'!$L$2:$L$201,MATCH(A3,'Salary Records'!$A$2:$A$201,0)) -> 0 | N3: =INDEX('Salary Records'!$E$2:$E$201,MATCH(A3,'Salary Records'!$A$2:$A$201,0)) -> 104500 | O3: =INDEX('Salary Records'!$O$2:$O$201,MATCH(A3,'Salary Records'!$A$2:$A$201,0)) -> 0 | P3: =INDEX('PF Records'!$H$2:$H$201,MATCH(A3,'PF Records'!$A$2:$A$201,0)) -> 12540 | Q3: =INDEX('PF Records'!$I$2:$I$201,MATCH(A3,'PF Records'!$A$2:$A$201,0)) -> 12540 | R3: =P3+Q3 -> 25080 | S3: =INDEX('Salary Records'!$S$2:$S$201,MATCH(A3,'Salary Records'!$A$2:$A$201,0)) -> 91960 | T3: =INDEX('Employee Master'!$I$2:$I$201,MATCH(A3,'Employee Master'!$A$2:$A$201,0)) -> 3 | U3: =INDEX('Employee Master'!$H$2:$H$201,MATCH(A3,'Employee Master'!$A$2:$A$201,0)) -> 3.9 | V3: =INDEX('Employee Master'!$J$2:$J$201,MATCH(A3,'Employee Master'!$A$2:$A$201,0)) -> 6.9
A4: EMP003 | B4: Ajay Kumar | C4: HR | D4: August 2026 | E4: =INDEX('Salary Records'!$F$2:$F$201,MATCH(A4,'Salary Records'!$A$2:$A$201,0)) -> 26 | F4: =INDEX('Salary Records'!$G$2:$G$201,MATCH(A4,'Salary Records'!$A$2:$A$201,0)) -> 20 | G4: =INDEX('Salary Records'!$H$2:$H$201,MATCH(A4,'Salary Records'!$A$2:$A$201,0)) -> 5 | H4: =INDEX('Salary Records'!$I$2:$I$201,MATCH(A4,'Salary Records'!$A$2:$A$201,0)) -> 1 | I4: =INDEX('Salary Records'!$J$2:$J$201,MATCH(A4,'Salary Records'!$A$2:$A$201,0)) -> 0 | J4: =ROUND(F4/E4*100,1) -> 76.9 | K4: 2 | L4: =INDEX('Salary Records'!$K$2:$K$201,MATCH(A4,'Salary Records'!$A$2:$A$201,0)) -> 2 | M4: =INDEX('Salary Records'!$L$2:$L$201,MATCH(A4,'Salary Records'!$A$2:$A$201,0)) -> 3 | N4: =INDEX('Salary Records'!$E$2:$E$201,MATCH(A4,'Salary Records'!$A$2:$A$201,0)) -> 23000 | O4: =INDEX('Salary Records'!$O$2:$O$201,MATCH(A4,'Salary Records'!$A$2:$A$201,0)) -> 2653.86 | P4: =INDEX('PF Records'!$H$2:$H$201,MATCH(A4,'PF Records'!$A$2:$A$201,0)) -> 2760 | Q4: =INDEX('PF Records'!$I$2:$I$201,MATCH(A4,'PF Records'!$A$2:$A$201,0)) -> 2760 | R4: =P4+Q4 -> 5520 | S4: =INDEX('Salary Records'!$S$2:$S$201,MATCH(A4,'Salary Records'!$A$2:$A$201,0)) -> 17586.14 | T4: =INDEX('Employee Master'!$I$2:$I$201,MATCH(A4,'Employee Master'!$A$2:$A$201,0)) -> 1.5 | U4: =INDEX('Employee Master'!$H$2:$H$201,MATCH(A4,'Employee Master'!$A$2:$A$201,0)) -> 3.4 | V4: =INDEX('Employee Master'!$J$2:$J$201,MATCH(A4,'Employee Master'!$A$2:$A$201,0)) -> 4.9
A5: EMP004 | B5: Pooja Tiwari | C5: Finance | D5: August 2026 | E5: =INDEX('Salary Records'!$F$2:$F$201,MATCH(A5,'Salary Records'!$A$2:$A$201,0)) -> 26 | F5: =INDEX('Salary Records'!$G$2:$G$201,MATCH(A5,'Salary Records'!$A$2:$A$201,0)) -> 24 | G5: =INDEX('Salary Records'!$H$2:$H$201,MATCH(A5,'Salary Records'!$A$2:$A$201,0)) -> 2 | H5: =INDEX('Salary Records'!$I$2:$I$201,MATCH(A5,'Salary Records'!$A$2:$A$201,0)) -> 0 | I5: =INDEX('Salary Records'!$J$2:$J$201,MATCH(A5,'Salary Records'!$A$2:$A$201,0)) -> 0 | J5: =ROUND(F5/E5*100,1) -> 92.3 | K5: 2 | L5: =INDEX('Salary Records'!$K$2:$K$201,MATCH(A5,'Salary Records'!$A$2:$A$201,0)) -> 2 | M5: =INDEX('Salary Records'!$L$2:$L$201,MATCH(A5,'Salary Records'!$A$2:$A$201,0)) -> 0 | N5: =INDEX('Salary Records'!$E$2:$E$201,MATCH(A5,'Salary Records'!$A$2:$A$201,0)) -> 33000 | O5: =INDEX('Salary Records'!$O$2:$O$201,MATCH(A5,'Salary Records'!$A$2:$A$201,0)) -> 0 | P5: =INDEX('PF Records'!$H$2:$H$201,MATCH(A5,'PF Records'!$A$2:$A$201,0)) -> 3960 | Q5: =INDEX('PF Records'!$I$2:$I$201,MATCH(A5,'PF Records'!$A$2:$A$201,0)) -> 3960 | R5: =P5+Q5 -> 7920 | S5: =INDEX('Salary Records'!$S$2:$S$201,MATCH(A5,'Salary Records'!$A$2:$A$201,0)) -> 29040 | T5: =INDEX('Employee Master'!$I$2:$I$201,MATCH(A5,'Employee Master'!$A$2:$A$201,0)) -> 7.2 | U5: =INDEX('Employee Master'!$H$2:$H$201,MATCH(A5,'Employee Master'!$A$2:$A$201,0)) -> 5.1 | V5: =INDEX('Employee Master'!$J$2:$J$201,MATCH(A5,'Employee Master'!$A$2:$A$201,0)) -> 12.3
A6: EMP005 | B6: Vandana Gupta | C6: Accounts | D6: August 2026 | E6: =INDEX('Salary Records'!$F$2:$F$201,MATCH(A6,'Salary Records'!$A$2:$A$201,0)) -> 26 | F6: =INDEX('Salary Records'!$G$2:$G$201,MATCH(A6,'Salary Records'!$A$2:$A$201,0)) -> 25 | G6: =INDEX('Salary Records'!$H$2:$H$201,MATCH(A6,'Salary Records'!$A$2:$A$201,0)) -> 1 | H6: =INDEX('Salary Records'!$I$2:$I$201,MATCH(A6,'Salary Records'!$A$2:$A$201,0)) -> 0 | I6: =INDEX('Salary Records'!$J$2:$J$201,MATCH(A6,'Salary Records'!$A$2:$A$201,0)) -> 0 | J6: =ROUND(F6/E6*100,1) -> 96.2 | K6: 2 | L6: =INDEX('Salary Records'!$K$2:$K$201,MATCH(A6,'Salary Records'!$A$2:$A$201,0)) -> 1 | M6: =INDEX('Salary Records'!$L$2:$L$201,MATCH(A6,'Salary Records'!$A$2:$A$201,0)) -> 0 | N6: =INDEX('Salary Records'!$E$2:$E$201,MATCH(A6,'Salary Records'!$A$2:$A$201,0)) -> 81000 | O6: =INDEX('Salary Records'!$O$2:$O$201,MATCH(A6,'Salary Records'!$A$2:$A$201,0)) -> 0 | P6: =INDEX('PF Records'!$H$2:$H$201,MATCH(A6,'PF Records'!$A$2:$A$201,0)) -> 9720 | Q6: =INDEX('PF Records'!$I$2:$I$201,MATCH(A6,'PF Records'!$A$2:$A$201,0)) -> 9720 | R6: =P6+Q6 -> 19440 | S6: =INDEX('Salary Records'!$S$2:$S$201,MATCH(A6,'Salary Records'!$A$2:$A$201,0)) -> 71280 | T6: =INDEX('Employee Master'!$I$2:$I$201,MATCH(A6,'Employee Master'!$A$2:$A$201,0)) -> 0.8 | U6: =INDEX('Employee Master'!$H$2:$H$201,MATCH(A6,'Employee Master'!$A$2:$A$201,0)) -> 3.4 | V6: =INDEX('Employee Master'!$J$2:$J$201,MATCH(A6,'Employee Master'!$A$2:$A$201,0)) -> 4.2
A7: EMP006 | B7: Seema Chauhan | C7: Sales | D7: August 2026 | E7: =INDEX('Salary Records'!$F$2:$F$201,MATCH(A7,'Salary Records'!$A$2:$A$201,0)) -> 26 | F7: =INDEX('Salary Records'!$G$2:$G$201,MATCH(A7,'Salary Records'!$A$2:$A$201,0)) -> 20 | G7: =INDEX('Salary Records'!$H$2:$H$201,MATCH(A7,'Salary Records'!$A$2:$A$201,0)) -> 3 | H7: =INDEX('Salary Records'!$I$2:$I$201,MATCH(A7,'Salary Records'!$A$2:$A$201,0)) -> 1 | I7: =INDEX('Salary Records'!$J$2:$J$201,MATCH(A7,'Salary Records'!$A$2:$A$201,0)) -> 2 | J7: =ROUND(F7/E7*100,1) -> 76.9 | K7: 2 | L7: =INDEX('Salary Records'!$K$2:$K$201,MATCH(A7,'Salary Records'!$A$2:$A$201,0)) -> 2 | M7: =INDEX('Salary Records'!$L$2:$L$201,MATCH(A7,'Salary Records'!$A$2:$A$201,0)) -> 1 | N7: =INDEX('Salary Records'!$E$2:$E$201,MATCH(A7,'Salary Records'!$A$2:$A$201,0)) -> 23000 | O7: =INDEX('Salary Records'!$O$2:$O$201,MATCH(A7,'Salary Records'!$A$2:$A$201,0)) -> 884.62 | P7: =INDEX('PF Records'!$H$2:$H$201,MATCH(A7,'PF Records'!$A$2:$A$201,0)) -> 2760 | Q7: =INDEX('PF Records'!$I$2:$I$201,MATCH(A7,'PF Records'!$A$2:$A$201,0)) -> 2760 | R7: =P7+Q7 -> 5520 | S7: =INDEX('Salary Records'!$S$2:$S$201,MATCH(A7,'Salary Records'!$A$2:$A$201,0)) -> 17586.14 | T7: =INDEX('Employee Master'!$I$2:$I$201,MATCH(A7,'Employee Master'!$A$2:$A$201,0)) -> 2.5 | U7: =INDEX('Employee Master'!$H$2:$H$201,MATCH(A7,'Employee Master'!$A$2:$A$201,0)) -> 0.3 | V7: =INDEX('Employee Master'!$J$2:$J$201,MATCH(A7,'Employee Master'!$A$2:$A$201,0)) -> 2.8
A8: EMP007 | B8: Vikram Sharma | C8: Marketing | D8: August 2026 | E8: =INDEX('Salary Records'!$F$2:$F$201,MATCH(A8,'Salary Records'!$A$2:$A$201,0)) -> 26 | F8: =INDEX('Salary Records'!$G$2:$G$201,MATCH(A8,'Salary Records'!$A$2:$A$201,0)) -> 26 | G8: =INDEX('Salary Records'!$H$2:$H$201,MATCH(A8,'Salary Records'!$A$2:$A$201,0)) -> 0 | H8: =INDEX('Salary Records'!$I$2:$I$201,MATCH(A8,'Salary Records'!$A$2:$A$201,0)) -> 0 | I8: =INDEX('Salary Records'!$J$2:$J$201,MATCH(A8,'Salary Records'!$A$2:$A$201,0)) -> 0 | J8: =ROUND(F8/E8*100,1) -> 100 | K8: 2 | L8: =INDEX('Salary Records'!$K$2:$K$201,MATCH(A8,'Salary Records'!$A$2:$A$201,0)) -> 0 | M8: =INDEX('Salary Records'!$L$2:$L$201,MATCH(A8,'Salary Records'!$A$2:$A$201,0)) -> 0 | N8: =INDEX('Salary Records'!$E$2:$E$201,MATCH(A8,'Salary Records'!$A$2:$A$201,0)) -> 34000 | O8: =INDEX('Salary Records'!$O$2:$O$201,MATCH(A8,'Salary Records'!$A$2:$A$201,0)) -> 0 | P8: =INDEX('PF Records'!$H$2:$H$201,MATCH(A8,'PF Records'!$A$2:$A$201,0)) -> 4080 | Q8: =INDEX('PF Records'!$I$2:$I$201,MATCH(A8,'PF Records'!$A$2:$A$201,0)) -> 4080 | R8: =P8+Q8 -> 8160 | S8: =INDEX('Salary Records'!$S$2:$S$201,MATCH(A8,'Salary Records'!$A$2:$A$201,0)) -> 29920 | T8: =INDEX('Employee Master'!$I$2:$I$201,MATCH(A8,'Employee Master'!$A$2:$A$201,0)) -> 7.2 | U8: =INDEX('Employee Master'!$H$2:$H$201,MATCH(A8,'Employee Master'!$A$2:$A$201,0)) -> 0.3 | V8: =INDEX('Employee Master'!$J$2:$J$201,MATCH(A8,'Employee Master'!$A$2:$A$201,0)) -> 7.5
A9: EMP008 | B9: Deepika Mehta | C9: Operations | D9: August 2026 | E9: =INDEX('Salary Records'!$F$2:$F$201,MATCH(A9,'Salary Records'!$A$2:$A$201,0)) -> 26 | F9: =INDEX('Salary Records'!$G$2:$G$201,MATCH(A9,'Salary Records'!$A$2:$A$201,0)) -> 26 | G9: =INDEX('Salary Records'!$H$2:$H$201,MATCH(A9,'Salary Records'!$A$2:$A$201,0)) -> 0 | H9: =INDEX('Salary Records'!$I$2:$I$201,MATCH(A9,'Salary Records'!$A$2:$A$201,0)) -> 0 | I9: =INDEX('Salary Records'!$J$2:$J$201,MATCH(A9,'Salary Records'!$A$2:$A$201,0)) -> 0 | J9: =ROUND(F9/E9*100,1) -> 100 | K9: 2 | L9: =INDEX('Salary Records'!$K$2:$K$201,MATCH(A9,'Salary Records'!$A$2:$A$201,0)) -> 0 | M9: =INDEX('Salary Records'!$L$2:$L$201,MATCH(A9,'Salary Records'!$A$2:$A$201,0)) -> 0 | N9: =INDEX('Salary Records'!$E$2:$E$201,MATCH(A9,'Salary Records'!$A$2:$A$201,0)) -> 30500 | O9: =INDEX('Salary Records'!$O$2:$O$201,MATCH(A9,'Salary Records'!$A$2:$A$201,0)) -> 0 | P9: =INDEX('PF Records'!$H$2:$H$201,MATCH(A9,'PF Records'!$A$2:$A$201,0)) -> 3660 | Q9: =INDEX('PF Records'!$I$2:$I$201,MATCH(A9,'PF Records'!$A$2:$A$201,0)) -> 3660 | R9: =P9+Q9 -> 7320 | S9: =INDEX('Salary Records'!$S$2:$S$201,MATCH(A9,'Salary Records'!$A$2:$A$201,0)) -> 26840 | T9: =INDEX('Employee Master'!$I$2:$I$201,MATCH(A9,'Employee Master'!$A$2:$A$201,0)) -> 6.3 | U9: =INDEX('Employee Master'!$H$2:$H$201,MATCH(A9,'Employee Master'!$A$2:$A$201,0)) -> 0 | V9: =INDEX('Employee Master'!$J$2:$J$201,MATCH(A9,'Employee Master'!$A$2:$A$201,0)) -> 6.3
A10: EMP009 | B10: Nandini Agarwal | C10: Administration | D10: August 2026 | E10: =INDEX('Salary Records'!$F$2:$F$201,MATCH(A10,'Salary Records'!$A$2:$A$201,0)) -> 26 | F10: =INDEX('Salary Records'!$G$2:$G$201,MATCH(A10,'Salary Records'!$A$2:$A$201,0)) -> 16 | G10: =INDEX('Salary Records'!$H$2:$H$201,MATCH(A10,'Salary Records'!$A$2:$A$201,0)) -> 9 | H10: =INDEX('Salary Records'!$I$2:$I$201,MATCH(A10,'Salary Records'!$A$2:$A$201,0)) -> 1 | I10: =INDEX('Salary Records'!$J$2:$J$201,MATCH(A10,'Salary Records'!$A$2:$A$201,0)) -> 0 | J10: =ROUND(F10/E10*100,1) -> 61.5 | K10: 2 | L10: =INDEX('Salary Records'!$K$2:$K$201,MATCH(A10,'Salary Records'!$A$2:$A$201,0)) -> 2 | M10: =INDEX('Salary Records'!$L$2:$L$201,MATCH(A10,'Salary Records'!$A$2:$A$201,0)) -> 7 | N10: =INDEX('Salary Records'!$E$2:$E$201,MATCH(A10,'Salary Records'!$A$2:$A$201,0)) -> 33500 | O10: =INDEX('Salary Records'!$O$2:$O$201,MATCH(A10,'Salary Records'!$A$2:$A$201,0)) -> 9019.22 | P10: =INDEX('PF Records'!$H$2:$H$201,MATCH(A10,'PF Records'!$A$2:$A$201,0)) -> 4020 | Q10: =INDEX('PF Records'!$I$2:$I$201,MATCH(A10,'PF Records'!$A$2:$A$201,0)) -> 4020 | R10: =P10+Q10 -> 8040 | S10: =INDEX('Salary Records'!$S$2:$S$201,MATCH(A10,'Salary Records'!$A$2:$A$201,0)) -> 20460.78 | T10: =INDEX('Employee Master'!$I$2:$I$201,MATCH(A10,'Employee Master'!$A$2:$A$201,0)) -> 1.7 | U10: =INDEX('Employee Master'!$H$2:$H$201,MATCH(A10,'Employee Master'!$A$2:$A$201,0)) -> 6 | V10: =INDEX('Employee Master'!$J$2:$J$201,MATCH(A10,'Employee Master'!$A$2:$A$201,0)) -> 7.7
A11: EMP010 | B11: Rachna Sharma | C11: Support | D11: August 2026 | E11: =INDEX('Salary Records'!$F$2:$F$201,MATCH(A11,'Salary Records'!$A$2:$A$201,0)) -> 26 | F11: =INDEX('Salary Records'!$G$2:$G$201,MATCH(A11,'Salary Records'!$A$2:$A$201,0)) -> 18 | G11: =INDEX('Salary Records'!$H$2:$H$201,MATCH(A11,'Salary Records'!$A$2:$A$201,0)) -> 5 | H11: =INDEX('Salary Records'!$I$2:$I$201,MATCH(A11,'Salary Records'!$A$2:$A$201,0)) -> 1 | I11: =INDEX('Salary Records'!$J$2:$J$201,MATCH(A11,'Salary Records'!$A$2:$A$201,0)) -> 2 | J11: =ROUND(F11/E11*100,1) -> 69.2 | K11: 2 | L11: =INDEX('Salary Records'!$K$2:$K$201,MATCH(A11,'Salary Records'!$A$2:$A$201,0)) -> 2 | M11: =INDEX('Salary Records'!$L$2:$L$201,MATCH(A11,'Salary Records'!$A$2:$A$201,0)) -> 3 | N11: =INDEX('Salary Records'!$E$2:$E$201,MATCH(A11,'Salary Records'!$A$2:$A$201,0)) -> 20500 | O11: =INDEX('Salary Records'!$O$2:$O$201,MATCH(A11,'Salary Records'!$A$2:$A$201,0)) -> 2365.38 | P11: =INDEX('PF Records'!$H$2:$H$201,MATCH(A11,'PF Records'!$A$2:$A$201,0)) -> 2460 | Q11: =INDEX('PF Records'!$I$2:$I$201,MATCH(A11,'PF Records'!$A$2:$A$201,0)) -> 2460 | R11: =P11+Q11 -> 4920 | S11: =INDEX('Salary Records'!$S$2:$S$201,MATCH(A11,'Salary Records'!$A$2:$A$201,0)) -> 14886.16 | T11: =INDEX('Employee Master'!$I$2:$I$201,MATCH(A11,'Employee Master'!$A$2:$A$201,0)) -> 6.7 | U11: =INDEX('Employee Master'!$H$2:$H$201,MATCH(A11,'Employee Master'!$A$2:$A$201,0)) -> 7.1 | V11: =INDEX('Employee Master'!$J$2:$J$201,MATCH(A11,'Employee Master'!$A$2:$A$201,0)) -> 13.8
A12: EMP011 | B12: Madhuri Mehta | C12: IT | D12: August 2026 | E12: =INDEX('Salary Records'!$F$2:$F$201,MATCH(A12,'Salary Records'!$A$2:$A$201,0)) -> 26 | F12: =INDEX('Salary Records'!$G$2:$G$201,MATCH(A12,'Salary Records'!$A$2:$A$201,0)) -> 23 | G12: =INDEX('Salary Records'!$H$2:$H$201,MATCH(A12,'Salary Records'!$A$2:$A$201,0)) -> 2 | H12: =INDEX('Salary Records'!$I$2:$I$201,MATCH(A12,'Salary Records'!$A$2:$A$201,0)) -> 1 | I12: =INDEX('Salary Records'!$J$2:$J$201,MATCH(A12,'Salary Records'!$A$2:$A$201,0)) -> 0 | J12: =ROUND(F12/E12*100,1) -> 88.5 | K12: 2 | L12: =INDEX('Salary Records'!$K$2:$K$201,MATCH(A12,'Salary Records'!$A$2:$A$201,0)) -> 2 | M12: =INDEX('Salary Records'!$L$2:$L$201,MATCH(A12,'Salary Records'!$A$2:$A$201,0)) -> 0 | N12: =INDEX('Salary Records'!$E$2:$E$201,MATCH(A12,'Salary Records'!$A$2:$A$201,0)) -> 124000 | O12: =INDEX('Salary Records'!$O$2:$O$201,MATCH(A12,'Salary Records'!$A$2:$A$201,0)) -> 0 | P12: =INDEX('PF Records'!$H$2:$H$201,MATCH(A12,'PF Records'!$A$2:$A$201,0)) -> 14880 | Q12: =INDEX('PF Records'!$I$2:$I$201,MATCH(A12,'PF Records'!$A$2:$A$201,0)) -> 14880 | R12: =P12+Q12 -> 29760 | S12: =INDEX('Salary Records'!$S$2:$S$201,MATCH(A12,'Salary Records'!$A$2:$A$201,0)) -> 104350.77 | T12: =INDEX('Employee Master'!$I$2:$I$201,MATCH(A12,'Employee Master'!$A$2:$A$201,0)) -> 1.2 | U12: =INDEX('Employee Master'!$H$2:$H$201,MATCH(A12,'Employee Master'!$A$2:$A$201,0)) -> 6.9 | V12: =INDEX('Employee Master'!$J$2:$J$201,MATCH(A12,'Employee Master'!$A$2:$A$201,0)) -> 8.1
A13: EMP012 | B13: Vandana Chauhan | C13: Engineering | D13: August 2026 | E13: =INDEX('Salary Records'!$F$2:$F$201,MATCH(A13,'Salary Records'!$A$2:$A$201,0)) -> 26 | F13: =INDEX('Salary Records'!$G$2:$G$201,MATCH(A13,'Salary Records'!$A$2:$A$201,0)) -> 26 | G13: =INDEX('Salary Records'!$H$2:$H$201,MATCH(A13,'Salary Records'!$A$2:$A$201,0)) -> 0 | H13: =INDEX('Salary Records'!$I$2:$I$201,MATCH(A13,'Salary Records'!$A$2:$A$201,0)) -> 0 | I13: =INDEX('Salary Records'!$J$2:$J$201,MATCH(A13,'Salary Records'!$A$2:$A$201,0)) -> 0 | J13: =ROUND(F13/E13*100,1) -> 100 | K13: 2 | L13: =INDEX('Salary Records'!$K$2:$K$201,MATCH(A13,'Salary Records'!$A$2:$A$201,0)) -> 0 | M13: =INDEX('Salary Records'!$L$2:$L$201,MATCH(A13,'Salary Records'!$A$2:$A$201,0)) -> 0 | N13: =INDEX('Salary Records'!$E$2:$E$201,MATCH(A13,'Salary Records'!$A$2:$A$201,0)) -> 101000 | O13: =INDEX('Salary Records'!$O$2:$O$201,MATCH(A13,'Salary Records'!$A$2:$A$201,0)) -> 0 | P13: =INDEX('PF Records'!$H$2:$H$201,MATCH(A13,'PF Records'!$A$2:$A$201,0)) -> 12120 | Q13: =INDEX('PF Records'!$I$2:$I$201,MATCH(A13,'PF Records'!$A$2:$A$201,0)) -> 12120 | R13: =P13+Q13 -> 24240 | S13: =INDEX('Salary Records'!$S$2:$S$201,MATCH(A13,'Salary Records'!$A$2:$A$201,0)) -> 88880 | T13: =INDEX('Employee Master'!$I$2:$I$201,MATCH(A13,'Employee Master'!$A$2:$A$201,0)) -> 0.8 | U13: =INDEX('Employee Master'!$H$2:$H$201,MATCH(A13,'Employee Master'!$A$2:$A$201,0)) -> 0.9 | V13: =INDEX('Employee Master'!$J$2:$J$201,MATCH(A13,'Employee Master'!$A$2:$A$201,0)) -> 1.7
... A201: EMP200 | B201: Pooja Chopra | C201: Support | D201: August 2026 | E201: =INDEX('Salary Records'!$F$2:$F$201,MATCH(A201,'Salary Records'!$A$2:$A$201,0)) -> 26 | F201: =INDEX('Salary Records'!$G$2:$G$201,MATCH(A201,'Salary Records'!$A$2:$A$201,0)) -> 21 | G201: =INDEX('Salary Records'!$H$2:$H$201,MATCH(A201,'Salary Records'!$A$2:$A$201,0)) -> 2 | H201: =INDEX('Salary Records'!$I$2:$I$201,MATCH(A201,'Salary Records'!$A$2:$A$201,0)) -> 1 | I201: =INDEX('Salary Records'!$J$2:$J$201,MATCH(A201,'Salary Records'!$A$2:$A$201,0)) -> 2 | J201: =ROUND(F201/E201*100,1) -> 80.8 | K201: 2 | L201: =INDEX('Salary Records'!$K$2:$K$201,MATCH(A201,'Salary Records'!$A$2:$A$201,0)) -> 2 | M201: =INDEX('Salary Records'!$L$2:$L$201,MATCH(A201,'Salary Records'!$A$2:$A$201,0)) -> 0 | N201: =INDEX('Salary Records'!$E$2:$E$201,MATCH(A201,'Salary Records'!$A$2:$A$201,0)) -> 62000 | O201: =INDEX('Salary Records'!$O$2:$O$201,MATCH(A201,'Salary Records'!$A$2:$A$201,0)) -> 0 | P201: =INDEX('PF Records'!$H$2:$H$201,MATCH(A201,'PF Records'!$A$2:$A$201,0)) -> 7440 | Q201: =INDEX('PF Records'!$I$2:$I$201,MATCH(A201,'PF Records'!$A$2:$A$201,0)) -> 7440 | R201: =P201+Q201 -> 14880 | S201: =INDEX('Salary Records'!$S$2:$S$201,MATCH(A201,'Salary Records'!$A$2:$A$201,0)) -> 49790.76 | T201: =INDEX('Employee Master'!$I$2:$I$201,MATCH(A201,'Employee Master'!$A$2:$A$201,0)) -> 5.6 | U201: =INDEX('Employee Master'!$H$2:$H$201,MATCH(A201,'Employee Master'!$A$2:$A$201,0)) -> 1.7 | V201: =INDEX('Employee Master'!$J$2:$J$201,MATCH(A201,'Employee Master'!$A$2:$A$201,0)) -> 7.3
